<?xml version="1.0" encoding="UTF-8"?>
<!-- Generated by org.testng.reporters.JUnitReportReporter -->
<testsuite hostname="DESKTOP-SHSVJLC" name="com.reachcp317.reach.UserRepositoryTest" tests="4" failures="3" timestamp="13 Dec 2018 05:29:21 GMT" time="0.026" errors="0">
  <testcase name="verifyLogin_detects_non_user" time="0.005" classname="com.reachcp317.reach.UserRepositoryTest">
    <failure type="java.lang.NullPointerException">
      <![CDATA[java.lang.NullPointerException
	at com.reachcp317.reach.UserRepository.verifyLogin(UserRepository.java:106)
	at com.reachcp317.reach.UserRepositoryTest.verifyLogin_detects_non_user(UserRepositoryTest.java:39)
	at sun.reflect.NativeMethodAccessorImpl.invoke0(Native Method)
	at sun.reflect.NativeMethodAccessorImpl.invoke(Unknown Source)
	at sun.reflect.DelegatingMethodAccessorImpl.invoke(Unknown Source)
	at java.lang.reflect.Method.invoke(Unknown Source)
	at org.testng.internal.MethodInvocationHelper.invokeMethod(MethodInvocationHelper.java:80)
	at org.testng.internal.Invoker.invokeMethod(Invoker.java:714)
	at org.testng.internal.Invoker.invokeTestMethod(Invoker.java:901)
	at org.testng.internal.Invoker.invokeTestMethods(Invoker.java:1231)
	at org.testng.internal.TestMethodWorker.invokeTestMethods(TestMethodWorker.java:127)
	at org.testng.internal.TestMethodWorker.run(TestMethodWorker.java:111)
	at org.testng.TestRunner.privateRun(TestRunner.java:767)
	at org.testng.TestRunner.run(TestRunner.java:617)
	at org.testng.SuiteRunner.runTest(SuiteRunner.java:334)
	at org.testng.SuiteRunner.runSequentially(SuiteRunner.java:329)
	at org.testng.SuiteRunner.privateRun(SuiteRunner.java:291)
	at org.testng.SuiteRunner.run(SuiteRunner.java:240)
	at org.testng.SuiteRunnerWorker.runSuite(SuiteRunnerWorker.java:52)
	at org.testng.SuiteRunnerWorker.run(SuiteRunnerWorker.java:86)
	at org.testng.TestNG.runSuitesSequentially(TestNG.java:1198)
	at org.testng.TestNG.runSuitesLocally(TestNG.java:1123)
	at org.testng.TestNG.run(TestNG.java:1031)
	at org.testng.remote.AbstractRemoteTestNG.run(AbstractRemoteTestNG.java:114)
	at org.testng.remote.RemoteTestNG.initAndRun(RemoteTestNG.java:251)
	at org.testng.remote.RemoteTestNG.main(RemoteTestNG.java:77)
]]>
    </failure>
  </testcase> <!-- verifyLogin_detects_non_user -->
  <testcase name="getByID_throwsException_withBadInput" time="0.008" classname="com.reachcp317.reach.UserRepositoryTest">
    <failure type="org.testng.TestException" message="
Expected exception org.springframework.dao.EmptyResultDataAccessException but got org.testng.TestException: 
Expected exception org.springframework.dao.EmptyResultDataAccessException but got java.lang.NullPointerException">
      <![CDATA[org.testng.TestException: 
Expected exception org.springframework.dao.EmptyResultDataAccessException but got org.testng.TestException: 
Expected exception org.springframework.dao.EmptyResultDataAccessException but got java.lang.NullPointerException
	at org.testng.internal.Invoker.handleInvocationResults(Invoker.java:1497)
	at org.testng.internal.Invoker.invokeTestMethods(Invoker.java:1245)
	at org.testng.internal.TestMethodWorker.invokeTestMethods(TestMethodWorker.java:127)
	at org.testng.internal.TestMethodWorker.run(TestMethodWorker.java:111)
	at org.testng.TestRunner.privateRun(TestRunner.java:767)
	at org.testng.TestRunner.run(TestRunner.java:617)
	at org.testng.SuiteRunner.runTest(SuiteRunner.java:334)
	at org.testng.SuiteRunner.runSequentially(SuiteRunner.java:329)
	at org.testng.SuiteRunner.privateRun(SuiteRunner.java:291)
	at org.testng.SuiteRunner.run(SuiteRunner.java:240)
	at org.testng.SuiteRunnerWorker.runSuite(SuiteRunnerWorker.java:52)
	at org.testng.SuiteRunnerWorker.run(SuiteRunnerWorker.java:86)
	at org.testng.TestNG.runSuitesSequentially(TestNG.java:1198)
	at org.testng.TestNG.runSuitesLocally(TestNG.java:1123)
	at org.testng.TestNG.run(TestNG.java:1031)
	at org.testng.remote.AbstractRemoteTestNG.run(AbstractRemoteTestNG.java:114)
	at org.testng.remote.RemoteTestNG.initAndRun(RemoteTestNG.java:251)
	at org.testng.remote.RemoteTestNG.main(RemoteTestNG.java:77)
Caused by: org.testng.TestException: 
Expected exception org.springframework.dao.EmptyResultDataAccessException but got java.lang.NullPointerException
	at org.testng.internal.Invoker.handleInvocationResults(Invoker.java:1497)
	at org.testng.internal.Invoker.invokeMethod(Invoker.java:754)
	at org.testng.internal.Invoker.invokeTestMethod(Invoker.java:901)
	at org.testng.internal.Invoker.invokeTestMethods(Invoker.java:1231)
	... 16 more
Caused by: java.lang.NullPointerException
	at com.reachcp317.reach.UserRepository.getById(UserRepository.java:80)
	at com.reachcp317.reach.UserRepositoryTest.getByID_throwsException_withBadInput(UserRepositoryTest.java:31)
	at sun.reflect.NativeMethodAccessorImpl.invoke0(Native Method)
	at sun.reflect.NativeMethodAccessorImpl.invoke(Unknown Source)
	at sun.reflect.DelegatingMethodAccessorImpl.invoke(Unknown Source)
	at java.lang.reflect.Method.invoke(Unknown Source)
	at org.testng.internal.MethodInvocationHelper.invokeMethod(MethodInvocationHelper.java:80)
	at org.testng.internal.Invoker.invokeMethod(Invoker.java:714)
	... 18 more
]]>
    </failure>
  </testcase> <!-- getByID_throwsException_withBadInput -->
  <testcase name="verifyLogin_throwsException_withBadInput" time="0.005" classname="com.reachcp317.reach.UserRepositoryTest">
    <failure type="org.testng.TestException" message="
Expected exception org.springframework.dao.EmptyResultDataAccessException but got org.testng.TestException: 
Expected exception org.springframework.dao.EmptyResultDataAccessException but got java.lang.NullPointerException">
      <![CDATA[org.testng.TestException: 
Expected exception org.springframework.dao.EmptyResultDataAccessException but got org.testng.TestException: 
Expected exception org.springframework.dao.EmptyResultDataAccessException but got java.lang.NullPointerException
	at org.testng.internal.Invoker.handleInvocationResults(Invoker.java:1497)
	at org.testng.internal.Invoker.invokeTestMethods(Invoker.java:1245)
	at org.testng.internal.TestMethodWorker.invokeTestMethods(TestMethodWorker.java:127)
	at org.testng.internal.TestMethodWorker.run(TestMethodWorker.java:111)
	at org.testng.TestRunner.privateRun(TestRunner.java:767)
	at org.testng.TestRunner.run(TestRunner.java:617)
	at org.testng.SuiteRunner.runTest(SuiteRunner.java:334)
	at org.testng.SuiteRunner.runSequentially(SuiteRunner.java:329)
	at org.testng.SuiteRunner.privateRun(SuiteRunner.java:291)
	at org.testng.SuiteRunner.run(SuiteRunner.java:240)
	at org.testng.SuiteRunnerWorker.runSuite(SuiteRunnerWorker.java:52)
	at org.testng.SuiteRunnerWorker.run(SuiteRunnerWorker.java:86)
	at org.testng.TestNG.runSuitesSequentially(TestNG.java:1198)
	at org.testng.TestNG.runSuitesLocally(TestNG.java:1123)
	at org.testng.TestNG.run(TestNG.java:1031)
	at org.testng.remote.AbstractRemoteTestNG.run(AbstractRemoteTestNG.java:114)
	at org.testng.remote.RemoteTestNG.initAndRun(RemoteTestNG.java:251)
	at org.testng.remote.RemoteTestNG.main(RemoteTestNG.java:77)
Caused by: org.testng.TestException: 
Expected exception org.springframework.dao.EmptyResultDataAccessException but got java.lang.NullPointerException
	at org.testng.internal.Invoker.handleInvocationResults(Invoker.java:1497)
	at org.testng.internal.Invoker.invokeMethod(Invoker.java:754)
	at org.testng.internal.Invoker.invokeTestMethod(Invoker.java:901)
	at org.testng.internal.Invoker.invokeTestMethods(Invoker.java:1231)
	... 16 more
Caused by: java.lang.NullPointerException
	at com.reachcp317.reach.UserRepository.verifyLogin(UserRepository.java:107)
	at com.reachcp317.reach.UserRepositoryTest.verifyLogin_throwsException_withBadInput(UserRepositoryTest.java:49)
	at sun.reflect.NativeMethodAccessorImpl.invoke0(Native Method)
	at sun.reflect.NativeMethodAccessorImpl.invoke(Unknown Source)
	at sun.reflect.DelegatingMethodAccessorImpl.invoke(Unknown Source)
	at java.lang.reflect.Method.invoke(Unknown Source)
	at org.testng.internal.MethodInvocationHelper.invokeMethod(MethodInvocationHelper.java:80)
	at org.testng.internal.Invoker.invokeMethod(Invoker.java:714)
	... 18 more
]]>
    </failure>
  </testcase> <!-- verifyLogin_throwsException_withBadInput -->
  <testcase name="createUser_Returns_Success" time="0.008" classname="com.reachcp317.reach.UserRepositoryTest"/>
</testsuite> <!-- com.reachcp317.reach.UserRepositoryTest -->
